[2024-01-30T19:10:35.297+0000] {taskinstance.py:1956} INFO - Dependencies all met for dep_context=non-requeueable deps ti=<TaskInstance: taskflow.chall_matches_to_df scheduled__2024-01-22T00:00:00+00:00 [queued]>
[2024-01-30T19:10:35.307+0000] {taskinstance.py:1956} INFO - Dependencies all met for dep_context=requeueable deps ti=<TaskInstance: taskflow.chall_matches_to_df scheduled__2024-01-22T00:00:00+00:00 [queued]>
[2024-01-30T19:10:35.308+0000] {taskinstance.py:2170} INFO - Starting attempt 1 of 1
[2024-01-30T19:10:35.364+0000] {taskinstance.py:2191} INFO - Executing <Task(_PythonDecoratedOperator): chall_matches_to_df> on 2024-01-22 00:00:00+00:00
[2024-01-30T19:10:35.377+0000] {standard_task_runner.py:60} INFO - Started process 121 to run task
[2024-01-30T19:10:35.379+0000] {standard_task_runner.py:87} INFO - Running: ['***', 'tasks', 'run', 'taskflow', 'chall_matches_to_df', 'scheduled__2024-01-22T00:00:00+00:00', '--job-id', '7', '--raw', '--subdir', 'DAGS_FOLDER/python_tft_tier.py', '--cfg-path', '/tmp/tmpau1ry1m5']
[2024-01-30T19:10:35.381+0000] {standard_task_runner.py:88} INFO - Job 7: Subtask chall_matches_to_df
[2024-01-30T19:10:35.549+0000] {task_command.py:423} INFO - Running <TaskInstance: taskflow.chall_matches_to_df scheduled__2024-01-22T00:00:00+00:00 [running]> on host 964619f82b50
[2024-01-30T19:10:35.828+0000] {taskinstance.py:2480} INFO - Exporting env vars: AIRFLOW_CTX_DAG_OWNER='***' AIRFLOW_CTX_DAG_ID='taskflow' AIRFLOW_CTX_TASK_ID='chall_matches_to_df' AIRFLOW_CTX_EXECUTION_DATE='2024-01-22T00:00:00+00:00' AIRFLOW_CTX_TRY_NUMBER='1' AIRFLOW_CTX_DAG_RUN_ID='scheduled__2024-01-22T00:00:00+00:00'
[2024-01-30T19:10:36.028+0000] {taskinstance.py:2698} ERROR - Task failed with exception
Traceback (most recent call last):
  File "/home/airflow/.local/lib/python3.8/site-packages/sqlalchemy/engine/base.py", line 1910, in _execute_context
    self.dialect.do_execute(
  File "/home/airflow/.local/lib/python3.8/site-packages/sqlalchemy/engine/default.py", line 736, in do_execute
    cursor.execute(statement, parameters)
psycopg2.errors.UniqueViolation: duplicate key value violates unique constraint "pg_type_typname_nsp_index"
DETAIL:  Key (typname, typnamespace)=(chall_tft_stats, 2200) already exists.


The above exception was the direct cause of the following exception:

Traceback (most recent call last):
  File "/home/airflow/.local/lib/python3.8/site-packages/airflow/models/taskinstance.py", line 433, in _execute_task
    result = execute_callable(context=context, **execute_callable_kwargs)
  File "/home/airflow/.local/lib/python3.8/site-packages/airflow/decorators/base.py", line 241, in execute
    return_value = super().execute(context)
  File "/home/airflow/.local/lib/python3.8/site-packages/airflow/operators/python.py", line 199, in execute
    return_value = self.execute_callable()
  File "/home/airflow/.local/lib/python3.8/site-packages/airflow/operators/python.py", line 216, in execute_callable
    return self.python_callable(*self.op_args, **self.op_kwargs)
  File "/opt/airflow/dags/python_tft_tier.py", line 123, in chall_matches_to_df
    df_without_underscore.to_sql('chall_tft_stats', engine, if_exists='replace', index=False)
  File "/home/airflow/.local/lib/python3.8/site-packages/pandas/core/generic.py", line 2878, in to_sql
    return sql.to_sql(
  File "/home/airflow/.local/lib/python3.8/site-packages/pandas/io/sql.py", line 769, in to_sql
    return pandas_sql.to_sql(
  File "/home/airflow/.local/lib/python3.8/site-packages/pandas/io/sql.py", line 1910, in to_sql
    table = self.prep_table(
  File "/home/airflow/.local/lib/python3.8/site-packages/pandas/io/sql.py", line 1814, in prep_table
    table.create()
  File "/home/airflow/.local/lib/python3.8/site-packages/pandas/io/sql.py", line 914, in create
    self._execute_create()
  File "/home/airflow/.local/lib/python3.8/site-packages/pandas/io/sql.py", line 900, in _execute_create
    self.table.create(bind=self.pd_sql.con)
  File "/home/airflow/.local/lib/python3.8/site-packages/sqlalchemy/sql/schema.py", line 962, in create
    bind._run_ddl_visitor(ddl.SchemaGenerator, self, checkfirst=checkfirst)
  File "/home/airflow/.local/lib/python3.8/site-packages/sqlalchemy/engine/base.py", line 2221, in _run_ddl_visitor
    visitorcallable(self.dialect, self, **kwargs).traverse_single(element)
  File "/home/airflow/.local/lib/python3.8/site-packages/sqlalchemy/sql/visitors.py", line 524, in traverse_single
    return meth(obj, **kw)
  File "/home/airflow/.local/lib/python3.8/site-packages/sqlalchemy/sql/ddl.py", line 899, in visit_table
    self.connection.execute(
  File "/home/airflow/.local/lib/python3.8/site-packages/sqlalchemy/engine/base.py", line 1385, in execute
    return meth(self, multiparams, params, _EMPTY_EXECUTION_OPTS)
  File "/home/airflow/.local/lib/python3.8/site-packages/sqlalchemy/sql/ddl.py", line 80, in _execute_on_connection
    return connection._execute_ddl(
  File "/home/airflow/.local/lib/python3.8/site-packages/sqlalchemy/engine/base.py", line 1477, in _execute_ddl
    ret = self._execute_context(
  File "/home/airflow/.local/lib/python3.8/site-packages/sqlalchemy/engine/base.py", line 1953, in _execute_context
    self._handle_dbapi_exception(
  File "/home/airflow/.local/lib/python3.8/site-packages/sqlalchemy/engine/base.py", line 2134, in _handle_dbapi_exception
    util.raise_(
  File "/home/airflow/.local/lib/python3.8/site-packages/sqlalchemy/util/compat.py", line 211, in raise_
    raise exception
  File "/home/airflow/.local/lib/python3.8/site-packages/sqlalchemy/engine/base.py", line 1910, in _execute_context
    self.dialect.do_execute(
  File "/home/airflow/.local/lib/python3.8/site-packages/sqlalchemy/engine/default.py", line 736, in do_execute
    cursor.execute(statement, parameters)
sqlalchemy.exc.IntegrityError: (psycopg2.errors.UniqueViolation) duplicate key value violates unique constraint "pg_type_typname_nsp_index"
DETAIL:  Key (typname, typnamespace)=(chall_tft_stats, 2200) already exists.

[SQL: 
CREATE TABLE chall_tft_stats (
	"Summoner Name" FLOAT(53), 
	"Augments" FLOAT(53), 
	"Units" FLOAT(53), 
	"Level" FLOAT(53), 
	"Placement" FLOAT(53)
)

]
(Background on this error at: https://sqlalche.me/e/14/gkpj)
[2024-01-30T19:10:36.075+0000] {taskinstance.py:1138} INFO - Marking task as FAILED. dag_id=taskflow, task_id=chall_matches_to_df, execution_date=20240122T000000, start_date=20240130T191035, end_date=20240130T191036
[2024-01-30T19:10:36.103+0000] {standard_task_runner.py:107} ERROR - Failed to execute job 7 for task chall_matches_to_df ((psycopg2.errors.UniqueViolation) duplicate key value violates unique constraint "pg_type_typname_nsp_index"
DETAIL:  Key (typname, typnamespace)=(chall_tft_stats, 2200) already exists.

[SQL: 
CREATE TABLE chall_tft_stats (
	"Summoner Name" FLOAT(53), 
	"Augments" FLOAT(53), 
	"Units" FLOAT(53), 
	"Level" FLOAT(53), 
	"Placement" FLOAT(53)
)

]
(Background on this error at: https://sqlalche.me/e/14/gkpj); 121)
[2024-01-30T19:10:36.114+0000] {local_task_job_runner.py:234} INFO - Task exited with return code 1
[2024-01-30T19:10:36.169+0000] {taskinstance.py:3280} INFO - 0 downstream tasks scheduled from follow-on schedule check
