[2024-02-01T22:24:31.740+0000] {taskinstance.py:1956} INFO - Dependencies all met for dep_context=non-requeueable deps ti=<TaskInstance: challenger_leaderboard.chall_matches_to_df manual__2024-02-01T22:24:29.832465+00:00 [queued]>
[2024-02-01T22:24:31.746+0000] {taskinstance.py:1956} INFO - Dependencies all met for dep_context=requeueable deps ti=<TaskInstance: challenger_leaderboard.chall_matches_to_df manual__2024-02-01T22:24:29.832465+00:00 [queued]>
[2024-02-01T22:24:31.746+0000] {taskinstance.py:2170} INFO - Starting attempt 1 of 1
[2024-02-01T22:24:31.762+0000] {taskinstance.py:2191} INFO - Executing <Task(_PythonDecoratedOperator): chall_matches_to_df> on 2024-02-01 22:24:29.832465+00:00
[2024-02-01T22:24:31.768+0000] {standard_task_runner.py:60} INFO - Started process 106 to run task
[2024-02-01T22:24:31.770+0000] {standard_task_runner.py:87} INFO - Running: ['***', 'tasks', 'run', 'challenger_leaderboard', 'chall_matches_to_df', 'manual__2024-02-01T22:24:29.832465+00:00', '--job-id', '278', '--raw', '--subdir', 'DAGS_FOLDER/python_tft_tier.py', '--cfg-path', '/tmp/tmpwnbvffcx']
[2024-02-01T22:24:31.770+0000] {standard_task_runner.py:88} INFO - Job 278: Subtask chall_matches_to_df
[2024-02-01T22:24:31.839+0000] {task_command.py:423} INFO - Running <TaskInstance: challenger_leaderboard.chall_matches_to_df manual__2024-02-01T22:24:29.832465+00:00 [running]> on host 964619f82b50
[2024-02-01T22:24:31.950+0000] {taskinstance.py:2480} INFO - Exporting env vars: AIRFLOW_CTX_DAG_OWNER='***' AIRFLOW_CTX_DAG_ID='challenger_leaderboard' AIRFLOW_CTX_TASK_ID='chall_matches_to_df' AIRFLOW_CTX_EXECUTION_DATE='2024-02-01T22:24:29.832465+00:00' AIRFLOW_CTX_TRY_NUMBER='1' AIRFLOW_CTX_DAG_RUN_ID='manual__2024-02-01T22:24:29.832465+00:00'
[2024-02-01T22:24:31.951+0000] {taskinstance.py:2698} ERROR - Task failed with exception
Traceback (most recent call last):
  File "/home/airflow/.local/lib/python3.8/site-packages/airflow/models/taskinstance.py", line 433, in _execute_task
    result = execute_callable(context=context, **execute_callable_kwargs)
  File "/home/airflow/.local/lib/python3.8/site-packages/airflow/decorators/base.py", line 241, in execute
    return_value = super().execute(context)
  File "/home/airflow/.local/lib/python3.8/site-packages/airflow/operators/python.py", line 199, in execute
    return_value = self.execute_callable()
  File "/home/airflow/.local/lib/python3.8/site-packages/airflow/operators/python.py", line 216, in execute_callable
    return self.python_callable(*self.op_args, **self.op_kwargs)
  File "/opt/airflow/dags/python_tft_tier.py", line 138, in chall_matches_to_df
    df_chall_matches = pd.DataFrame(chall_matches)
  File "/home/airflow/.local/lib/python3.8/site-packages/pandas/core/frame.py", line 774, in __init__
    data = list(data)
  File "/home/airflow/.local/lib/python3.8/site-packages/airflow/models/xcom_arg.py", line 270, in __iter__
    raise TypeError("'XComArg' object is not iterable")
TypeError: 'XComArg' object is not iterable
[2024-02-01T22:24:31.972+0000] {taskinstance.py:1138} INFO - Marking task as FAILED. dag_id=challenger_leaderboard, task_id=chall_matches_to_df, execution_date=20240201T222429, start_date=20240201T222431, end_date=20240201T222431
[2024-02-01T22:24:31.983+0000] {standard_task_runner.py:107} ERROR - Failed to execute job 278 for task chall_matches_to_df ('XComArg' object is not iterable; 106)
[2024-02-01T22:24:32.022+0000] {local_task_job_runner.py:234} INFO - Task exited with return code 1
[2024-02-01T22:24:32.053+0000] {taskinstance.py:3280} INFO - 0 downstream tasks scheduled from follow-on schedule check
